<?xml version="1.0" ?>
<sdf version='1.4'>
  <world name="model_world">
    <!-- Ground Plane -->
    <include>
      <uri>model://sun</uri>
    </include>

    <model name="gplane">
      <pose>0.000000 0.000000 0.000000 0 0 0</pose>
      <link name="plane">
        <pose>0.000000 0.000000 0.000000 0.000000 -0.000000 0.000000</pose>
        <collision name="plane">
          <pose>0.000000 0.000000 0.000000 0.000000 -0.000000 0.000000</pose>
          <geometry>
            <plane>
              <normal>0.000000 0.000000 1.00000</normal>
            </plane>
          </geometry>
          <surface>

          <friction>
              <ode>
                <mu>100.000000</mu>
                <mu2>100.000000</mu2>
              </ode>
            </friction>
          </surface>

        </collision>
      </link>
    </model>

    <model name="my_robot_2">
      <static>false</static>
      <pose>0 1 0 0 0 0</pose>
      <link name='chassis'>
        <pose>0 0 .1 0 0 0</pose>
        <collision name='collision'>
          <geometry>
            <box>
              <size>.4 .2 .1</size>
            </box>
          </geometry>
        </collision>

        <visual name='visual'>
          <geometry>
            <box>
              <size>.4 .2 .1</size>
            </box>
          </geometry>
        </visual>

        <collision name='caster_collision'>
            <pose>-0.15 0 -0.05 0 0 0</pose>
            <geometry>
                <sphere>
                <radius>.05</radius>
              </sphere>
            </geometry>

            <surface>
              <friction>
                <ode>
                  <mu>0</mu>
                  <mu2>0</mu2>
                  <slip1>1.0</slip1>
                  <slip2>1.0</slip2>
                </ode>
              </friction>
            </surface>
          </collision>

          <visual name='caster_visual'>
            <pose>-0.15 0 -0.05 0 0 0</pose>
            <geometry>
              <sphere>
                <radius>.05</radius>
              </sphere>
            </geometry>
          </visual>
      </link>

      <link name="left_wheel">
        <pose>0.1 0.13 0.1 0 1.5707 1.5707</pose>
        <collision name="collision">
          <geometry>
            <cylinder>
              <radius>.1</radius>
              <length>.05</length>
            </cylinder>
          </geometry>
        </collision>
        <visual name="visual">
          <geometry>
            <cylinder>
              <radius>.1</radius>
              <length>.05</length>
            </cylinder>
          </geometry>
        </visual>
      </link>

      <link name="right_wheel">
        <pose>0.1 -0.13 0.1 0 1.5707 1.5707</pose>
        <collision name="collision">
          <geometry>
            <cylinder>
              <radius>.1</radius>
              <length>.05</length>
            </cylinder>
          </geometry>
        </collision>
        <visual name="visual">
          <geometry>
            <cylinder>
              <radius>.1</radius>
              <length>.05</length>
            </cylinder>
          </geometry>
        </visual>
      </link>      

      <link name="camera_link">
        <gravity>0</gravity>
        <pose>0.2 0 0.2 0 0 0</pose> 
	
        <visual name="camera_link_visual">
          <pose>0 0 0 0 0 0</pose>
          <geometry>
            <box>
              <size>0.01 0.1 0.02</size>
            </box>
          </geometry>
          <material>
            <ambient>0.1 0.1 0.1 1</ambient>
            <diffuse>0.1 0.1 0.2 1</diffuse>
            <specular>0 0 0 0</specular>
            <emissive>0 0 0 1</emissive>
          </material>
        </visual>      
        <sensor type="ray" name="head_hokuyo_sensor">
          <pose>0 0 0 0 0 0</pose>
          <visualize>1</visualize>
          <update_rate>20</update_rate>
          <ray>
            <scan>
              <horizontal>
                <samples>540</samples>
                <resolution>1</resolution>
                <min_angle>-1.570796</min_angle>
                <max_angle>1.570796</max_angle>
              </horizontal>
            </scan>
            <range>
              <min>0.10</min>
              <max>10.0</max>
              <resolution>0.01</resolution>
            </range>
            <noise>
              <type>gaussian</type>
              <!-- Noise parameters based on published spec for Hokuyo laser
                  achieving "+-30mm" accuracy at range < 10m.  A mean of 0.0m and
                  stddev of 0.01m will put 99.7% of samples within 0.03m of the true
                  reading. -->
              <mean>0.0</mean>
              <stddev>0.01</stddev>
            </noise>
          </ray>
          <plugin name="gazebo_ros_head_hokuyo_controller" filename="libgazebo_ros_laser.so">
            <topicName>/scan</topicName>
            <frameName>camera_link</frameName>
          </plugin>
        </sensor>
      </link> 

      <joint name="camera_joint" type="revolute">
        <axis>
          <xyz>0 0 0</xyz>
        </axis>        
        <parent>chassis</parent>
        <child>camera_link</child>
      </joint>  

      <joint type="revolute" name="left_wheel_hinge">
        <pose>0 0 -0.03 0 0 0</pose>
        <child>left_wheel</child>
        <parent>chassis</parent>
        <axis>
          <xyz>0 1 0</xyz>
        </axis>
      </joint>

      <joint type="revolute" name="right_wheel_hinge">
        <pose>0 0 0.03 0 0 0</pose>
        <child>right_wheel</child>
        <parent>chassis</parent>
        <axis>
          <xyz>0 1 0</xyz>
        </axis>
      </joint>

      <plugin filename="libgazebo_ros_diff_drive.so" name="differential_drive_controller">
        <alwaysOn>true</alwaysOn>
        <updateRate>20</updateRate>
        <leftJoint>left_wheel_hinge</leftJoint>
        <rightJoint>right_wheel_hinge</rightJoint>
        <wheelSeparation>0.4</wheelSeparation>
        <wheelDiameter>0.2</wheelDiameter>
        <torque>0.1</torque>
        <commandTopic>cmd_vel</commandTopic>
        <odometryTopic>odom</odometryTopic>
        <odometryFrame>odom</odometryFrame>
        <robotBaseFrame>link_chassis</robotBaseFrame>
      </plugin>
    </model>

    <model name="my_robot">
      <static>false</static>
      <link name='chassis'>
        <pose>0 0 .1 0 0 0</pose>
        <collision name='collision'>
          <geometry>
            <box>
              <size>.4 .2 .1</size>
            </box>
          </geometry>
        </collision>

        <visual name='visual'>
          <geometry>
            <box>
              <size>.4 .2 .1</size>
            </box>
          </geometry>
        </visual>

        <collision name='caster_collision'>
            <pose>-0.15 0 -0.05 0 0 0</pose>
            <geometry>
                <sphere>
                <radius>.05</radius>
              </sphere>
            </geometry>

            <surface>
              <friction>
                <ode>
                  <mu>0</mu>
                  <mu2>0</mu2>
                  <slip1>1.0</slip1>
                  <slip2>1.0</slip2>
                </ode>
              </friction>
            </surface>
          </collision>

          <visual name='caster_visual'>
            <pose>-0.15 0 -0.05 0 0 0</pose>
            <geometry>
              <sphere>
                <radius>.05</radius>
              </sphere>
            </geometry>
          </visual>
      </link>

      <link name="left_wheel">
        <pose>0.1 0.13 0.1 0 1.5707 1.5707</pose>
        <collision name="collision">
          <geometry>
            <cylinder>
              <radius>.1</radius>
              <length>.05</length>
            </cylinder>
          </geometry>
        </collision>
        <visual name="visual">
          <geometry>
            <cylinder>
              <radius>.1</radius>
              <length>.05</length>
            </cylinder>
          </geometry>
        </visual>
      </link>

      <link name="right_wheel">
        <pose>0.1 -0.13 0.1 0 1.5707 1.5707</pose>
        <collision name="collision">
          <geometry>
            <cylinder>
              <radius>.1</radius>
              <length>.05</length>
            </cylinder>
          </geometry>
        </collision>
        <visual name="visual">
          <geometry>
            <cylinder>
              <radius>.1</radius>
              <length>.05</length>
            </cylinder>
          </geometry>
        </visual>
      </link>      

      <link name="camera_link">
        <gravity>0</gravity>
        <pose>0.2 0 0.2 0 0 0</pose> 
	
        <visual name="camera_link_visual">
          <pose>0 0 0 0 0 0</pose>
          <geometry>
            <box>
              <size>0.01 0.1 0.02</size>
            </box>
          </geometry>
          <material>
            <ambient>0.1 0.1 0.1 1</ambient>
            <diffuse>0.1 0.1 0.2 1</diffuse>
            <specular>0 0 0 0</specular>
            <emissive>0 0 0 1</emissive>
          </material>
        </visual>      
        <sensor type="ray" name="head_hokuyo_sensor">
          <pose>0 0 0 0 0 0</pose>
          <visualize>1</visualize>
          <update_rate>20</update_rate>
          <ray>
            <scan>
              <horizontal>
                <samples>540</samples>
                <resolution>1</resolution>
                <min_angle>-1.570796</min_angle>
                <max_angle>1.570796</max_angle>
              </horizontal>
            </scan>
            <range>
              <min>0.10</min>
              <max>10.0</max>
              <resolution>0.01</resolution>
            </range>
            <noise>
              <type>gaussian</type>
              <!-- Noise parameters based on published spec for Hokuyo laser
                  achieving "+-30mm" accuracy at range < 10m.  A mean of 0.0m and
                  stddev of 0.01m will put 99.7% of samples within 0.03m of the true
                  reading. -->
              <mean>0.0</mean>
              <stddev>0.01</stddev>
            </noise>
          </ray>
          <plugin name="gazebo_ros_head_hokuyo_controller" filename="libgazebo_ros_laser.so">
            <topicName>/scan_2</topicName>
            <frameName>camera_link</frameName>
          </plugin>
        </sensor>
      </link> 

      <joint name="camera_joint" type="revolute">
        <axis>
          <xyz>0 0 0</xyz>
        </axis>        
        <parent>chassis</parent>
        <child>camera_link</child>
      </joint>  

      <joint type="revolute" name="left_wheel_hinge">
        <pose>0 0 -0.03 0 0 0</pose>
        <child>left_wheel</child>
        <parent>chassis</parent>
        <axis>
          <xyz>0 1 0</xyz>
        </axis>
      </joint>

      <joint type="revolute" name="right_wheel_hinge">
        <pose>0 0 0.03 0 0 0</pose>
        <child>right_wheel</child>
        <parent>chassis</parent>
        <axis>
          <xyz>0 1 0</xyz>
        </axis>
      </joint>
    </model>

    <model name='box'>
      <pose>3 0 0.25 0 0 0</pose>
      <static>true</static>
      <link name="box">
        <self_collide>0</self_collide>
        <pose>0 0 0 0 0 0</pose>
        <collision name="box_col">
          <pose>0 0 0 0 0 0</pose>
          <geometry>
            <box>
              <size>1 1 0.50</size>
            </box>
          </geometry>
          <surface>
            <contact>
              <collide_bitmask>1</collide_bitmask>
            </contact>
          </surface>
        </collision>
        <visual name="box_visual">
          <pose>0 0 0 0 0 0</pose>
          <geometry>
            <box>
              <size>1 1 0.50</size>
            </box>
          </geometry>
          <material>
            <ambient>0.1 0.1 0.1 1</ambient>
            <diffuse>0.1 0.1 0.2 1</diffuse>
            <specular>0 0 0 0</specular>
            <emissive>0 0 0 1</emissive>
          </material>
        </visual>
      </link>        
    </model>

    <model name='cylinder'>
      <pose>2 2 0.25 0 0 0</pose>
      <static>true</static>
      <link name="cylinder">
        <self_collide>0</self_collide>
        <pose>0 0 0 0 0 0</pose>
        <collision name="cylinder_col">
          <pose>0 0 0 0 0 0</pose>
          <geometry>
            <cylinder>
             <radius>0.2</radius> 
             <length>0.5</length>            
            </cylinder>
          </geometry>
          <surface>
            <contact>
              <collide_bitmask>1</collide_bitmask>
            </contact>
          </surface>
        </collision>
        <visual name="cylinder_visual">
          <pose>0 0 0 0 0 0</pose>
          <geometry>
            <cylinder>
             <radius>0.2</radius> 
             <length>0.5</length>       
            </cylinder>
          </geometry>
          <material>
            <ambient>0.1 0.1 0.1 1</ambient>
            <diffuse>0.1 0.1 0.2 1</diffuse>
            <specular>0 0 0 0</specular>
            <emissive>0 0 0 1</emissive>
          </material>
        </visual>
      </link>        
    </model>    
  </world>
</sdf>